2025-01-05 00:19:58,420 (INFO)- django.utils.autoreload- Watching for file changes with StatReloader
2025-01-05 00:22:07,419 (INFO)- django.utils.autoreload- Watching for file changes with StatReloader
2025-01-05 00:22:48,332 (WARNING)- django.request- Not Found: /
2025-01-05 00:23:01,288 (WARNING)- django.request- Method Not Allowed: /api/login/
2025-01-05 00:23:21,519 (INFO)- home.views- Login API request received
2025-01-05 00:23:22,798 (WARNING)- django.request- Unauthorized: /api/login/
2025-01-05 00:25:26,818 (INFO)- django.utils.autoreload- C:\Users\hp\OneDrive\Desktop\Examino\project\home\views.py changed, reloading.
2025-01-05 00:25:28,170 (INFO)- django.utils.autoreload- Watching for file changes with StatReloader
2025-01-05 00:26:40,584 (INFO)- home.views- Login API request received
2025-01-05 00:26:41,658 (ERROR)- home.views- Login error: 'User' object has no attribute 'type_of'
2025-01-05 00:26:41,740 (WARNING)- django.request- Bad Request: /api/login/
2025-01-05 00:27:19,059 (INFO)- django.utils.autoreload- C:\Users\hp\OneDrive\Desktop\Examino\project\home\views.py changed, reloading.
2025-01-05 00:27:20,158 (INFO)- django.utils.autoreload- Watching for file changes with StatReloader
2025-01-05 00:27:45,431 (INFO)- home.views- Login API request received
2025-01-05 00:27:46,619 (INFO)- home.views- dhruvi
2025-01-05 00:27:46,619 (ERROR)- home.views- Login error: 'User' object has no attribute 'type_of'
2025-01-05 00:27:46,721 (WARNING)- django.request- Bad Request: /api/login/
2025-01-05 00:37:18,139 (INFO)- django.utils.autoreload- C:\Users\hp\OneDrive\Desktop\Examino\project\home\views.py changed, reloading.
2025-01-05 00:37:19,635 (INFO)- django.utils.autoreload- Watching for file changes with StatReloader
2025-01-05 00:37:40,298 (INFO)- django.utils.autoreload- C:\Users\hp\OneDrive\Desktop\Examino\project\home\views.py changed, reloading.
2025-01-05 00:37:41,833 (INFO)- django.utils.autoreload- Watching for file changes with StatReloader
2025-01-05 00:38:08,130 (INFO)- django.utils.autoreload- C:\Users\hp\OneDrive\Desktop\Examino\project\home\views.py changed, reloading.
2025-01-05 00:38:09,548 (INFO)- django.utils.autoreload- Watching for file changes with StatReloader
2025-01-05 00:38:41,308 (INFO)- home.views- Login API request received
2025-01-05 00:38:41,315 (INFO)- home.views- Found user object: dhruvi
2025-01-05 00:38:42,410 (INFO)- home.views- dhruvi
2025-01-05 00:38:42,419 (ERROR)- home.views- Login error: 'User' object has no attribute 'type_of'
2025-01-05 00:38:42,489 (WARNING)- django.request- Bad Request: /api/login/
2025-01-05 00:41:34,711 (INFO)- django.utils.autoreload- C:\Users\hp\OneDrive\Desktop\Examino\project\home\admin.py changed, reloading.
2025-01-05 00:41:35,950 (INFO)- django.utils.autoreload- Watching for file changes with StatReloader
2025-01-05 00:42:46,081 (INFO)- django.utils.autoreload- C:\Users\hp\OneDrive\Desktop\Examino\project\project\settings.py changed, reloading.
2025-01-05 00:42:47,164 (INFO)- django.utils.autoreload- Watching for file changes with StatReloader
2025-01-05 00:43:23,126 (INFO)- django.utils.autoreload- C:\Users\hp\OneDrive\Desktop\Examino\project\project\settings.py changed, reloading.
2025-01-05 00:43:24,507 (INFO)- django.utils.autoreload- Watching for file changes with StatReloader
2025-01-05 00:43:59,818 (INFO)- django.utils.autoreload- Watching for file changes with StatReloader
2025-01-05 00:44:25,228 (INFO)- home.views- Login API request received
2025-01-05 00:44:25,236 (INFO)- home.views- Found user object: dhruvi
2025-01-05 00:44:26,320 (INFO)- home.views- dhruvi
2025-01-05 00:44:26,320 (ERROR)- home.views- Login error: 'User' object has no attribute 'type_of'
2025-01-05 00:44:26,423 (WARNING)- django.request- Bad Request: /api/login/
2025-01-05 00:45:15,300 (WARNING)- django.request- Not Found: /
2025-01-05 00:45:22,809 (WARNING)- django.request- Not Found: /api/admin/
2025-01-05 00:47:52,319 (INFO)- django.utils.autoreload- C:\Users\hp\OneDrive\Desktop\Examino\project\project\settings.py changed, reloading.
2025-01-05 00:47:53,681 (INFO)- django.utils.autoreload- Watching for file changes with StatReloader
2025-01-05 01:01:03,009 (INFO)- django.utils.autoreload- C:\Users\hp\OneDrive\Desktop\Examino\project\project\settings.py changed, reloading.
2025-01-05 01:01:03,929 (INFO)- django.utils.autoreload- Watching for file changes with StatReloader
2025-01-05 22:39:07,126 (INFO)- django.utils.autoreload- Watching for file changes with StatReloader
2025-01-05 22:39:38,992 (INFO)- home.views- Login API request received
2025-01-05 22:39:38,992 (INFO)- home.views- Found user object: dhruvi
2025-01-05 22:39:40,080 (INFO)- home.views- dhruvi
2025-01-05 22:39:40,080 (ERROR)- home.views- Login error: 'User' object has no attribute 'type_of'
2025-01-05 22:39:40,100 (WARNING)- django.request- Bad Request: /api/login/
2025-01-05 23:09:26,380 (INFO)- django.utils.autoreload- Watching for file changes with StatReloader
2025-01-05 23:09:53,077 (WARNING)- django.request- Unauthorized: /api/login/
2025-01-05 23:10:26,456 (INFO)- django.utils.autoreload- C:\Users\hp\OneDrive\Desktop\Examino\project\home\views.py changed, reloading.
2025-01-05 23:10:27,421 (INFO)- django.utils.autoreload- Watching for file changes with StatReloader
2025-01-05 23:10:54,516 (ERROR)- django.request- Internal Server Error: /api/login/
Traceback (most recent call last):
  File "C:\Users\hp\AppData\Local\Programs\Python\Python312\Lib\site-packages\django\core\handlers\exception.py", line 55, in inner
    response = get_response(request)
               ^^^^^^^^^^^^^^^^^^^^^
  File "C:\Users\hp\AppData\Local\Programs\Python\Python312\Lib\site-packages\django\core\handlers\base.py", line 220, in _get_response
    response = response.render()
               ^^^^^^^^^^^^^^^^^
  File "C:\Users\hp\AppData\Local\Programs\Python\Python312\Lib\site-packages\django\template\response.py", line 114, in render
    self.content = self.rendered_content
                   ^^^^^^^^^^^^^^^^^^^^^
  File "C:\Users\hp\AppData\Local\Programs\Python\Python312\Lib\site-packages\rest_framework\response.py", line 74, in rendered_content
    ret = renderer.render(self.data, accepted_media_type, context)
          ^^^^^^^^^^^^^^^^^^^^^^^^^^^^^^^^^^^^^^^^^^^^^^^^^^^^^^^^
  File "C:\Users\hp\AppData\Local\Programs\Python\Python312\Lib\site-packages\rest_framework\renderers.py", line 100, in render
    ret = json.dumps(
          ^^^^^^^^^^^
  File "C:\Users\hp\AppData\Local\Programs\Python\Python312\Lib\site-packages\rest_framework\utils\json.py", line 25, in dumps
    return json.dumps(*args, **kwargs)
           ^^^^^^^^^^^^^^^^^^^^^^^^^^^
  File "C:\Users\hp\AppData\Local\Programs\Python\Python312\Lib\json\__init__.py", line 238, in dumps
    **kw).encode(obj)
          ^^^^^^^^^^^
  File "C:\Users\hp\AppData\Local\Programs\Python\Python312\Lib\json\encoder.py", line 200, in encode
    chunks = self.iterencode(o, _one_shot=True)
             ^^^^^^^^^^^^^^^^^^^^^^^^^^^^^^^^^^
  File "C:\Users\hp\AppData\Local\Programs\Python\Python312\Lib\json\encoder.py", line 258, in iterencode
    return _iterencode(o, 0)
           ^^^^^^^^^^^^^^^^^
  File "C:\Users\hp\AppData\Local\Programs\Python\Python312\Lib\site-packages\rest_framework\utils\encoders.py", line 67, in default
    return super().default(obj)
           ^^^^^^^^^^^^^^^^^^^^
  File "C:\Users\hp\AppData\Local\Programs\Python\Python312\Lib\json\encoder.py", line 180, in default
    raise TypeError(f'Object of type {o.__class__.__name__} '
TypeError: Object of type UserNew is not JSON serializable
2025-01-05 23:13:57,506 (INFO)- django.utils.autoreload- C:\Users\hp\OneDrive\Desktop\Examino\project\home\views.py changed, reloading.
2025-01-05 23:13:58,316 (INFO)- django.utils.autoreload- Watching for file changes with StatReloader
2025-01-05 23:14:11,496 (ERROR)- django.request- Internal Server Error: /api/login/
Traceback (most recent call last):
  File "C:\Users\hp\AppData\Local\Programs\Python\Python312\Lib\site-packages\django\core\handlers\exception.py", line 55, in inner
    response = get_response(request)
               ^^^^^^^^^^^^^^^^^^^^^
  File "C:\Users\hp\AppData\Local\Programs\Python\Python312\Lib\site-packages\django\core\handlers\base.py", line 220, in _get_response
    response = response.render()
               ^^^^^^^^^^^^^^^^^
  File "C:\Users\hp\AppData\Local\Programs\Python\Python312\Lib\site-packages\django\template\response.py", line 114, in render
    self.content = self.rendered_content
                   ^^^^^^^^^^^^^^^^^^^^^
  File "C:\Users\hp\AppData\Local\Programs\Python\Python312\Lib\site-packages\rest_framework\response.py", line 74, in rendered_content
    ret = renderer.render(self.data, accepted_media_type, context)
          ^^^^^^^^^^^^^^^^^^^^^^^^^^^^^^^^^^^^^^^^^^^^^^^^^^^^^^^^
  File "C:\Users\hp\AppData\Local\Programs\Python\Python312\Lib\site-packages\rest_framework\renderers.py", line 100, in render
    ret = json.dumps(
          ^^^^^^^^^^^
  File "C:\Users\hp\AppData\Local\Programs\Python\Python312\Lib\site-packages\rest_framework\utils\json.py", line 25, in dumps
    return json.dumps(*args, **kwargs)
           ^^^^^^^^^^^^^^^^^^^^^^^^^^^
  File "C:\Users\hp\AppData\Local\Programs\Python\Python312\Lib\json\__init__.py", line 238, in dumps
    **kw).encode(obj)
          ^^^^^^^^^^^
  File "C:\Users\hp\AppData\Local\Programs\Python\Python312\Lib\json\encoder.py", line 200, in encode
    chunks = self.iterencode(o, _one_shot=True)
             ^^^^^^^^^^^^^^^^^^^^^^^^^^^^^^^^^^
  File "C:\Users\hp\AppData\Local\Programs\Python\Python312\Lib\json\encoder.py", line 258, in iterencode
    return _iterencode(o, 0)
           ^^^^^^^^^^^^^^^^^
  File "C:\Users\hp\AppData\Local\Programs\Python\Python312\Lib\site-packages\rest_framework\utils\encoders.py", line 67, in default
    return super().default(obj)
           ^^^^^^^^^^^^^^^^^^^^
  File "C:\Users\hp\AppData\Local\Programs\Python\Python312\Lib\json\encoder.py", line 180, in default
    raise TypeError(f'Object of type {o.__class__.__name__} '
TypeError: Object of type UserNew is not JSON serializable
2025-01-05 23:14:35,407 (ERROR)- django.request- Internal Server Error: /api/login/
Traceback (most recent call last):
  File "C:\Users\hp\AppData\Local\Programs\Python\Python312\Lib\site-packages\django\core\handlers\exception.py", line 55, in inner
    response = get_response(request)
               ^^^^^^^^^^^^^^^^^^^^^
  File "C:\Users\hp\AppData\Local\Programs\Python\Python312\Lib\site-packages\django\core\handlers\base.py", line 220, in _get_response
    response = response.render()
               ^^^^^^^^^^^^^^^^^
  File "C:\Users\hp\AppData\Local\Programs\Python\Python312\Lib\site-packages\django\template\response.py", line 114, in render
    self.content = self.rendered_content
                   ^^^^^^^^^^^^^^^^^^^^^
  File "C:\Users\hp\AppData\Local\Programs\Python\Python312\Lib\site-packages\rest_framework\response.py", line 74, in rendered_content
    ret = renderer.render(self.data, accepted_media_type, context)
          ^^^^^^^^^^^^^^^^^^^^^^^^^^^^^^^^^^^^^^^^^^^^^^^^^^^^^^^^
  File "C:\Users\hp\AppData\Local\Programs\Python\Python312\Lib\site-packages\rest_framework\renderers.py", line 100, in render
    ret = json.dumps(
          ^^^^^^^^^^^
  File "C:\Users\hp\AppData\Local\Programs\Python\Python312\Lib\site-packages\rest_framework\utils\json.py", line 25, in dumps
    return json.dumps(*args, **kwargs)
           ^^^^^^^^^^^^^^^^^^^^^^^^^^^
  File "C:\Users\hp\AppData\Local\Programs\Python\Python312\Lib\json\__init__.py", line 238, in dumps
    **kw).encode(obj)
          ^^^^^^^^^^^
  File "C:\Users\hp\AppData\Local\Programs\Python\Python312\Lib\json\encoder.py", line 200, in encode
    chunks = self.iterencode(o, _one_shot=True)
             ^^^^^^^^^^^^^^^^^^^^^^^^^^^^^^^^^^
  File "C:\Users\hp\AppData\Local\Programs\Python\Python312\Lib\json\encoder.py", line 258, in iterencode
    return _iterencode(o, 0)
           ^^^^^^^^^^^^^^^^^
  File "C:\Users\hp\AppData\Local\Programs\Python\Python312\Lib\site-packages\rest_framework\utils\encoders.py", line 67, in default
    return super().default(obj)
           ^^^^^^^^^^^^^^^^^^^^
  File "C:\Users\hp\AppData\Local\Programs\Python\Python312\Lib\json\encoder.py", line 180, in default
    raise TypeError(f'Object of type {o.__class__.__name__} '
TypeError: Object of type UserNew is not JSON serializable
2025-01-05 23:15:13,709 (INFO)- django.utils.autoreload- C:\Users\hp\OneDrive\Desktop\Examino\project\home\views.py changed, reloading.
2025-01-05 23:15:14,879 (INFO)- django.utils.autoreload- Watching for file changes with StatReloader
2025-01-05 23:15:32,151 (INFO)- django.utils.autoreload- C:\Users\hp\OneDrive\Desktop\Examino\project\home\views.py changed, reloading.
2025-01-05 23:15:33,077 (INFO)- django.utils.autoreload- Watching for file changes with StatReloader
2025-01-05 23:15:46,631 (WARNING)- django.request- Unauthorized: /api/login/
2025-01-05 23:16:14,914 (INFO)- django.utils.autoreload- C:\Users\hp\OneDrive\Desktop\Examino\project\home\views.py changed, reloading.
2025-01-05 23:16:15,976 (INFO)- django.utils.autoreload- Watching for file changes with StatReloader
2025-01-05 23:16:29,248 (WARNING)- django.request- Unauthorized: /api/login/
2025-01-05 23:16:42,246 (WARNING)- django.request- Unauthorized: /api/login/
2025-01-05 23:17:28,576 (WARNING)- django.request- Unauthorized: /api/login/
2025-01-05 23:18:19,596 (WARNING)- django.request- Unauthorized: /api/login/
2025-01-05 23:18:51,506 (INFO)- django.utils.autoreload- C:\Users\hp\OneDrive\Desktop\Examino\project\home\views.py changed, reloading.
2025-01-05 23:18:52,581 (INFO)- django.utils.autoreload- Watching for file changes with StatReloader
2025-01-05 23:19:01,809 (WARNING)- django.request- Unauthorized: /api/login/
2025-01-05 23:23:52,496 (INFO)- home.views- api-request-reached
2025-01-05 23:57:50,380 (INFO)- django.utils.autoreload- C:\Users\hp\OneDrive\Desktop\Examino\project\home\views.py changed, reloading.
2025-01-05 23:57:52,059 (INFO)- django.utils.autoreload- Watching for file changes with StatReloader
2025-01-05 23:58:09,490 (INFO)- django.utils.autoreload- C:\Users\hp\OneDrive\Desktop\Examino\project\home\views.py changed, reloading.
2025-01-05 23:58:10,871 (INFO)- django.utils.autoreload- Watching for file changes with StatReloader
2025-01-05 23:58:58,383 (INFO)- home.views- api-request-reached
2025-01-05 23:58:59,723 (ERROR)- django.request- Internal Server Error: /api/login/
Traceback (most recent call last):
  File "C:\Users\hp\AppData\Local\Programs\Python\Python312\Lib\site-packages\django\core\handlers\exception.py", line 55, in inner
    response = get_response(request)
               ^^^^^^^^^^^^^^^^^^^^^
  File "C:\Users\hp\AppData\Local\Programs\Python\Python312\Lib\site-packages\django\core\handlers\base.py", line 197, in _get_response
    response = wrapped_callback(request, *callback_args, **callback_kwargs)
               ^^^^^^^^^^^^^^^^^^^^^^^^^^^^^^^^^^^^^^^^^^^^^^^^^^^^^^^^^^^^
  File "C:\Users\hp\AppData\Local\Programs\Python\Python312\Lib\site-packages\django\views\decorators\csrf.py", line 65, in _view_wrapper
    return view_func(request, *args, **kwargs)
           ^^^^^^^^^^^^^^^^^^^^^^^^^^^^^^^^^^^
  File "C:\Users\hp\AppData\Local\Programs\Python\Python312\Lib\site-packages\django\views\generic\base.py", line 104, in view
    return self.dispatch(request, *args, **kwargs)
           ^^^^^^^^^^^^^^^^^^^^^^^^^^^^^^^^^^^^^^^
  File "C:\Users\hp\AppData\Local\Programs\Python\Python312\Lib\site-packages\rest_framework\views.py", line 509, in dispatch
    response = self.handle_exception(exc)
               ^^^^^^^^^^^^^^^^^^^^^^^^^^
  File "C:\Users\hp\AppData\Local\Programs\Python\Python312\Lib\site-packages\rest_framework\views.py", line 469, in handle_exception
    self.raise_uncaught_exception(exc)
  File "C:\Users\hp\AppData\Local\Programs\Python\Python312\Lib\site-packages\rest_framework\views.py", line 480, in raise_uncaught_exception
    raise exc
  File "C:\Users\hp\AppData\Local\Programs\Python\Python312\Lib\site-packages\rest_framework\views.py", line 506, in dispatch
    response = handler(request, *args, **kwargs)
               ^^^^^^^^^^^^^^^^^^^^^^^^^^^^^^^^^
  File "C:\Users\hp\OneDrive\Desktop\Examino\project\home\views.py", line 44, in post
    if user.type_of == type_of_input:
       ^^^^^^^^^^^^
AttributeError: 'User' object has no attribute 'type_of'
2025-01-06 00:03:09,798 (INFO)- django.utils.autoreload- C:\Users\hp\OneDrive\Desktop\Examino\project\home\views.py changed, reloading.
2025-01-06 00:03:11,126 (INFO)- django.utils.autoreload- Watching for file changes with StatReloader
2025-01-08 22:04:05,015 (INFO)- django.utils.autoreload- Watching for file changes with StatReloader
2025-01-08 22:04:08,130 (INFO)- django.utils.autoreload- C:\Users\hp\OneDrive\Desktop\Examino\project\home\views.py changed, reloading.
2025-01-08 22:04:09,423 (INFO)- django.utils.autoreload- Watching for file changes with StatReloader
2025-01-08 22:04:18,585 (INFO)- home.views- api-request-reached
2025-01-08 22:04:18,742 (ERROR)- django.request- Internal Server Error: /api/type/
Traceback (most recent call last):
  File "C:\Users\hp\AppData\Local\Programs\Python\Python312\Lib\site-packages\django\core\handlers\exception.py", line 55, in inner
    response = get_response(request)
               ^^^^^^^^^^^^^^^^^^^^^
  File "C:\Users\hp\AppData\Local\Programs\Python\Python312\Lib\site-packages\django\core\handlers\base.py", line 197, in _get_response
    response = wrapped_callback(request, *callback_args, **callback_kwargs)
               ^^^^^^^^^^^^^^^^^^^^^^^^^^^^^^^^^^^^^^^^^^^^^^^^^^^^^^^^^^^^
  File "C:\Users\hp\AppData\Local\Programs\Python\Python312\Lib\site-packages\django\views\decorators\csrf.py", line 65, in _view_wrapper
    return view_func(request, *args, **kwargs)
           ^^^^^^^^^^^^^^^^^^^^^^^^^^^^^^^^^^^
  File "C:\Users\hp\AppData\Local\Programs\Python\Python312\Lib\site-packages\django\views\generic\base.py", line 104, in view
    return self.dispatch(request, *args, **kwargs)
           ^^^^^^^^^^^^^^^^^^^^^^^^^^^^^^^^^^^^^^^
  File "C:\Users\hp\AppData\Local\Programs\Python\Python312\Lib\site-packages\rest_framework\views.py", line 509, in dispatch
    response = self.handle_exception(exc)
               ^^^^^^^^^^^^^^^^^^^^^^^^^^
  File "C:\Users\hp\AppData\Local\Programs\Python\Python312\Lib\site-packages\rest_framework\views.py", line 469, in handle_exception
    self.raise_uncaught_exception(exc)
  File "C:\Users\hp\AppData\Local\Programs\Python\Python312\Lib\site-packages\rest_framework\views.py", line 480, in raise_uncaught_exception
    raise exc
  File "C:\Users\hp\AppData\Local\Programs\Python\Python312\Lib\site-packages\rest_framework\views.py", line 506, in dispatch
    response = handler(request, *args, **kwargs)
               ^^^^^^^^^^^^^^^^^^^^^^^^^^^^^^^^^
  File "C:\Users\hp\OneDrive\Desktop\Examino\project\home\views.py", line 58, in post
    if serializer.is_valid():
       ^^^^^^^^^^^^^^^^^^^^^
  File "C:\Users\hp\AppData\Local\Programs\Python\Python312\Lib\site-packages\rest_framework\serializers.py", line 223, in is_valid
    self._validated_data = self.run_validation(self.initial_data)
                           ^^^^^^^^^^^^^^^^^^^^^^^^^^^^^^^^^^^^^^
  File "C:\Users\hp\AppData\Local\Programs\Python\Python312\Lib\site-packages\rest_framework\serializers.py", line 442, in run_validation
    value = self.to_internal_value(data)
            ^^^^^^^^^^^^^^^^^^^^^^^^^^^^
  File "C:\Users\hp\AppData\Local\Programs\Python\Python312\Lib\site-packages\rest_framework\serializers.py", line 495, in to_internal_value
    for field in fields:
  File "C:\Users\hp\AppData\Local\Programs\Python\Python312\Lib\site-packages\rest_framework\serializers.py", line 378, in _writable_fields
    for field in self.fields.values():
                 ^^^^^^^^^^^
  File "C:\Users\hp\AppData\Local\Programs\Python\Python312\Lib\site-packages\django\utils\functional.py", line 47, in __get__
    res = instance.__dict__[self.name] = self.func(instance)
                                         ^^^^^^^^^^^^^^^^^^^
  File "C:\Users\hp\AppData\Local\Programs\Python\Python312\Lib\site-packages\rest_framework\serializers.py", line 372, in fields
    for key, value in self.get_fields().items():
                      ^^^^^^^^^^^^^^^^^
  File "C:\Users\hp\AppData\Local\Programs\Python\Python312\Lib\site-packages\rest_framework\serializers.py", line 1078, in get_fields
    info = model_meta.get_field_info(model)
           ^^^^^^^^^^^^^^^^^^^^^^^^^^^^^^^^
  File "C:\Users\hp\AppData\Local\Programs\Python\Python312\Lib\site-packages\rest_framework\utils\model_meta.py", line 35, in get_field_info
    opts = model._meta.concrete_model._meta
           ^^^^^^^^^^^
AttributeError: type object 'UserType' has no attribute '_meta'
2025-01-08 22:04:28,954 (INFO)- home.views- api-request-reached
2025-01-08 22:04:29,032 (ERROR)- django.request- Internal Server Error: /api/type/
Traceback (most recent call last):
  File "C:\Users\hp\AppData\Local\Programs\Python\Python312\Lib\site-packages\django\core\handlers\exception.py", line 55, in inner
    response = get_response(request)
               ^^^^^^^^^^^^^^^^^^^^^
  File "C:\Users\hp\AppData\Local\Programs\Python\Python312\Lib\site-packages\django\core\handlers\base.py", line 197, in _get_response
    response = wrapped_callback(request, *callback_args, **callback_kwargs)
               ^^^^^^^^^^^^^^^^^^^^^^^^^^^^^^^^^^^^^^^^^^^^^^^^^^^^^^^^^^^^
  File "C:\Users\hp\AppData\Local\Programs\Python\Python312\Lib\site-packages\django\views\decorators\csrf.py", line 65, in _view_wrapper
    return view_func(request, *args, **kwargs)
           ^^^^^^^^^^^^^^^^^^^^^^^^^^^^^^^^^^^
  File "C:\Users\hp\AppData\Local\Programs\Python\Python312\Lib\site-packages\django\views\generic\base.py", line 104, in view
    return self.dispatch(request, *args, **kwargs)
           ^^^^^^^^^^^^^^^^^^^^^^^^^^^^^^^^^^^^^^^
  File "C:\Users\hp\AppData\Local\Programs\Python\Python312\Lib\site-packages\rest_framework\views.py", line 509, in dispatch
    response = self.handle_exception(exc)
               ^^^^^^^^^^^^^^^^^^^^^^^^^^
  File "C:\Users\hp\AppData\Local\Programs\Python\Python312\Lib\site-packages\rest_framework\views.py", line 469, in handle_exception
    self.raise_uncaught_exception(exc)
  File "C:\Users\hp\AppData\Local\Programs\Python\Python312\Lib\site-packages\rest_framework\views.py", line 480, in raise_uncaught_exception
    raise exc
  File "C:\Users\hp\AppData\Local\Programs\Python\Python312\Lib\site-packages\rest_framework\views.py", line 506, in dispatch
    response = handler(request, *args, **kwargs)
               ^^^^^^^^^^^^^^^^^^^^^^^^^^^^^^^^^
  File "C:\Users\hp\OneDrive\Desktop\Examino\project\home\views.py", line 58, in post
    if serializer.is_valid():
       ^^^^^^^^^^^^^^^^^^^^^
  File "C:\Users\hp\AppData\Local\Programs\Python\Python312\Lib\site-packages\rest_framework\serializers.py", line 223, in is_valid
    self._validated_data = self.run_validation(self.initial_data)
                           ^^^^^^^^^^^^^^^^^^^^^^^^^^^^^^^^^^^^^^
  File "C:\Users\hp\AppData\Local\Programs\Python\Python312\Lib\site-packages\rest_framework\serializers.py", line 442, in run_validation
    value = self.to_internal_value(data)
            ^^^^^^^^^^^^^^^^^^^^^^^^^^^^
  File "C:\Users\hp\AppData\Local\Programs\Python\Python312\Lib\site-packages\rest_framework\serializers.py", line 495, in to_internal_value
    for field in fields:
  File "C:\Users\hp\AppData\Local\Programs\Python\Python312\Lib\site-packages\rest_framework\serializers.py", line 378, in _writable_fields
    for field in self.fields.values():
                 ^^^^^^^^^^^
  File "C:\Users\hp\AppData\Local\Programs\Python\Python312\Lib\site-packages\django\utils\functional.py", line 47, in __get__
    res = instance.__dict__[self.name] = self.func(instance)
                                         ^^^^^^^^^^^^^^^^^^^
  File "C:\Users\hp\AppData\Local\Programs\Python\Python312\Lib\site-packages\rest_framework\serializers.py", line 372, in fields
    for key, value in self.get_fields().items():
                      ^^^^^^^^^^^^^^^^^
  File "C:\Users\hp\AppData\Local\Programs\Python\Python312\Lib\site-packages\rest_framework\serializers.py", line 1078, in get_fields
    info = model_meta.get_field_info(model)
           ^^^^^^^^^^^^^^^^^^^^^^^^^^^^^^^^
  File "C:\Users\hp\AppData\Local\Programs\Python\Python312\Lib\site-packages\rest_framework\utils\model_meta.py", line 35, in get_field_info
    opts = model._meta.concrete_model._meta
           ^^^^^^^^^^^
AttributeError: type object 'UserType' has no attribute '_meta'
2025-01-08 22:09:01,495 (INFO)- home.views- api-request-reached
2025-01-08 22:09:01,840 (ERROR)- django.request- Internal Server Error: /api/type/
Traceback (most recent call last):
  File "C:\Users\hp\AppData\Local\Programs\Python\Python312\Lib\site-packages\django\core\handlers\exception.py", line 55, in inner
    response = get_response(request)
               ^^^^^^^^^^^^^^^^^^^^^
  File "C:\Users\hp\AppData\Local\Programs\Python\Python312\Lib\site-packages\django\core\handlers\base.py", line 197, in _get_response
    response = wrapped_callback(request, *callback_args, **callback_kwargs)
               ^^^^^^^^^^^^^^^^^^^^^^^^^^^^^^^^^^^^^^^^^^^^^^^^^^^^^^^^^^^^
  File "C:\Users\hp\AppData\Local\Programs\Python\Python312\Lib\site-packages\django\views\decorators\csrf.py", line 65, in _view_wrapper
    return view_func(request, *args, **kwargs)
           ^^^^^^^^^^^^^^^^^^^^^^^^^^^^^^^^^^^
  File "C:\Users\hp\AppData\Local\Programs\Python\Python312\Lib\site-packages\django\views\generic\base.py", line 104, in view
    return self.dispatch(request, *args, **kwargs)
           ^^^^^^^^^^^^^^^^^^^^^^^^^^^^^^^^^^^^^^^
  File "C:\Users\hp\AppData\Local\Programs\Python\Python312\Lib\site-packages\rest_framework\views.py", line 509, in dispatch
    response = self.handle_exception(exc)
               ^^^^^^^^^^^^^^^^^^^^^^^^^^
  File "C:\Users\hp\AppData\Local\Programs\Python\Python312\Lib\site-packages\rest_framework\views.py", line 469, in handle_exception
    self.raise_uncaught_exception(exc)
  File "C:\Users\hp\AppData\Local\Programs\Python\Python312\Lib\site-packages\rest_framework\views.py", line 480, in raise_uncaught_exception
    raise exc
  File "C:\Users\hp\AppData\Local\Programs\Python\Python312\Lib\site-packages\rest_framework\views.py", line 506, in dispatch
    response = handler(request, *args, **kwargs)
               ^^^^^^^^^^^^^^^^^^^^^^^^^^^^^^^^^
  File "C:\Users\hp\OneDrive\Desktop\Examino\project\home\views.py", line 58, in post
    if serializer.is_valid():
       ^^^^^^^^^^^^^^^^^^^^^
  File "C:\Users\hp\AppData\Local\Programs\Python\Python312\Lib\site-packages\rest_framework\serializers.py", line 223, in is_valid
    self._validated_data = self.run_validation(self.initial_data)
                           ^^^^^^^^^^^^^^^^^^^^^^^^^^^^^^^^^^^^^^
  File "C:\Users\hp\AppData\Local\Programs\Python\Python312\Lib\site-packages\rest_framework\serializers.py", line 442, in run_validation
    value = self.to_internal_value(data)
            ^^^^^^^^^^^^^^^^^^^^^^^^^^^^
  File "C:\Users\hp\AppData\Local\Programs\Python\Python312\Lib\site-packages\rest_framework\serializers.py", line 495, in to_internal_value
    for field in fields:
  File "C:\Users\hp\AppData\Local\Programs\Python\Python312\Lib\site-packages\rest_framework\serializers.py", line 378, in _writable_fields
    for field in self.fields.values():
                 ^^^^^^^^^^^
  File "C:\Users\hp\AppData\Local\Programs\Python\Python312\Lib\site-packages\django\utils\functional.py", line 47, in __get__
    res = instance.__dict__[self.name] = self.func(instance)
                                         ^^^^^^^^^^^^^^^^^^^
  File "C:\Users\hp\AppData\Local\Programs\Python\Python312\Lib\site-packages\rest_framework\serializers.py", line 372, in fields
    for key, value in self.get_fields().items():
                      ^^^^^^^^^^^^^^^^^
  File "C:\Users\hp\AppData\Local\Programs\Python\Python312\Lib\site-packages\rest_framework\serializers.py", line 1078, in get_fields
    info = model_meta.get_field_info(model)
           ^^^^^^^^^^^^^^^^^^^^^^^^^^^^^^^^
  File "C:\Users\hp\AppData\Local\Programs\Python\Python312\Lib\site-packages\rest_framework\utils\model_meta.py", line 35, in get_field_info
    opts = model._meta.concrete_model._meta
           ^^^^^^^^^^^
AttributeError: type object 'UserType' has no attribute '_meta'
2025-01-08 22:09:52,285 (INFO)- django.utils.autoreload- C:\Users\hp\OneDrive\Desktop\Examino\project\home\models.py changed, reloading.
2025-01-08 22:09:53,259 (INFO)- django.utils.autoreload- Watching for file changes with StatReloader
2025-01-08 22:10:00,720 (INFO)- home.views- api-request-reached
2025-01-08 22:10:00,724 (WARNING)- django.request- Bad Request: /api/type/
2025-01-08 22:23:23,419 (INFO)- django.utils.autoreload- Watching for file changes with StatReloader
2025-01-08 22:23:50,930 (INFO)- home.views- api-request-reached
2025-01-08 22:23:51,920 (INFO)- home.views- jane
2025-01-08 22:23:52,160 (ERROR)- django.request- Internal Server Error: /api/login/
Traceback (most recent call last):
  File "C:\Users\hp\AppData\Local\Programs\Python\Python312\Lib\site-packages\django\core\handlers\exception.py", line 55, in inner
    response = get_response(request)
               ^^^^^^^^^^^^^^^^^^^^^
  File "C:\Users\hp\AppData\Local\Programs\Python\Python312\Lib\site-packages\django\core\handlers\base.py", line 220, in _get_response
    response = response.render()
               ^^^^^^^^^^^^^^^^^
  File "C:\Users\hp\AppData\Local\Programs\Python\Python312\Lib\site-packages\django\template\response.py", line 114, in render
    self.content = self.rendered_content
                   ^^^^^^^^^^^^^^^^^^^^^
  File "C:\Users\hp\AppData\Local\Programs\Python\Python312\Lib\site-packages\rest_framework\response.py", line 74, in rendered_content
    ret = renderer.render(self.data, accepted_media_type, context)
          ^^^^^^^^^^^^^^^^^^^^^^^^^^^^^^^^^^^^^^^^^^^^^^^^^^^^^^^^
  File "C:\Users\hp\AppData\Local\Programs\Python\Python312\Lib\site-packages\rest_framework\renderers.py", line 100, in render
    ret = json.dumps(
          ^^^^^^^^^^^
  File "C:\Users\hp\AppData\Local\Programs\Python\Python312\Lib\site-packages\rest_framework\utils\json.py", line 25, in dumps
    return json.dumps(*args, **kwargs)
           ^^^^^^^^^^^^^^^^^^^^^^^^^^^
  File "C:\Users\hp\AppData\Local\Programs\Python\Python312\Lib\json\__init__.py", line 238, in dumps
    **kw).encode(obj)
          ^^^^^^^^^^^
  File "C:\Users\hp\AppData\Local\Programs\Python\Python312\Lib\json\encoder.py", line 200, in encode
    chunks = self.iterencode(o, _one_shot=True)
             ^^^^^^^^^^^^^^^^^^^^^^^^^^^^^^^^^^
  File "C:\Users\hp\AppData\Local\Programs\Python\Python312\Lib\json\encoder.py", line 258, in iterencode
    return _iterencode(o, 0)
           ^^^^^^^^^^^^^^^^^
  File "C:\Users\hp\AppData\Local\Programs\Python\Python312\Lib\site-packages\rest_framework\utils\encoders.py", line 67, in default
    return super().default(obj)
           ^^^^^^^^^^^^^^^^^^^^
  File "C:\Users\hp\AppData\Local\Programs\Python\Python312\Lib\json\encoder.py", line 180, in default
    raise TypeError(f'Object of type {o.__class__.__name__} '
TypeError: Object of type User is not JSON serializable
2025-01-08 22:26:58,411 (INFO)- django.utils.autoreload- C:\Users\hp\OneDrive\Desktop\Examino\project\api\serializers.py changed, reloading.
2025-01-08 22:26:59,140 (INFO)- django.utils.autoreload- Watching for file changes with StatReloader
2025-01-08 22:27:34,585 (INFO)- django.utils.autoreload- C:\Users\hp\OneDrive\Desktop\Examino\project\api\serializers.py changed, reloading.
2025-01-08 22:27:35,270 (INFO)- django.utils.autoreload- Watching for file changes with StatReloader
2025-01-08 22:27:48,525 (INFO)- home.views- api-request-reached
2025-01-08 22:27:48,529 (WARNING)- django.request- Unauthorized: /api/login/
2025-01-08 22:27:57,016 (INFO)- home.views- api-request-reached
2025-01-08 22:27:57,016 (WARNING)- django.request- Unauthorized: /api/login/
2025-01-08 22:28:08,519 (INFO)- home.views- api-request-reached
2025-01-08 22:28:08,519 (WARNING)- django.request- Unauthorized: /api/login/
2025-01-08 22:30:13,061 (INFO)- django.utils.autoreload- Watching for file changes with StatReloader
2025-01-08 22:30:26,030 (INFO)- home.views- api-request-reached
2025-01-08 22:30:26,034 (WARNING)- django.request- Unauthorized: /api/login/
2025-01-08 22:31:03,767 (INFO)- home.views- api-request-reached
2025-01-08 22:31:03,769 (WARNING)- django.request- Bad Request: /api/register/
2025-01-08 22:31:34,785 (INFO)- django.utils.autoreload- C:\Users\hp\OneDrive\Desktop\Examino\project\api\serializers.py changed, reloading.
2025-01-08 22:31:35,525 (INFO)- django.utils.autoreload- Watching for file changes with StatReloader
2025-01-08 22:31:43,985 (INFO)- home.views- api-request-reached
2025-01-08 22:31:43,989 (WARNING)- django.request- Bad Request: /api/register/
2025-01-08 23:17:14,248 (INFO)- django.utils.autoreload- Watching for file changes with StatReloader
2025-01-08 23:17:44,041 (INFO)- home.views- api-request-reached
2025-01-08 23:17:44,049 (WARNING)- django.request- Bad Request: /api/register/
2025-01-08 23:18:10,516 (INFO)- home.views- api-request-reached
2025-01-08 23:18:10,518 (WARNING)- django.request- Bad Request: /api/register/
2025-01-08 23:18:46,680 (INFO)- home.views- api-request-reached
2025-01-08 23:18:46,688 (WARNING)- django.request- Bad Request: /api/register/
2025-01-08 23:19:32,997 (INFO)- django.utils.autoreload- C:\Users\hp\OneDrive\Desktop\Examino\project\api\serializers.py changed, reloading.
2025-01-08 23:19:34,088 (INFO)- django.utils.autoreload- Watching for file changes with StatReloader
2025-01-08 23:20:25,671 (INFO)- home.views- api-request-reached
2025-01-08 23:20:25,690 (WARNING)- django.request- Bad Request: /api/register/
2025-01-09 10:26:14,412 (INFO)- django.utils.autoreload- Watching for file changes with StatReloader
2025-01-09 10:26:39,192 (INFO)- home.views- api-request-reached
2025-01-09 10:26:40,246 (INFO)- home.views- dhruvi
2025-01-09 10:26:40,476 (ERROR)- django.request- Internal Server Error: /api/login/
Traceback (most recent call last):
  File "C:\Users\hp\AppData\Local\Programs\Python\Python312\Lib\site-packages\django\core\handlers\exception.py", line 55, in inner
    response = get_response(request)
               ^^^^^^^^^^^^^^^^^^^^^
  File "C:\Users\hp\AppData\Local\Programs\Python\Python312\Lib\site-packages\django\core\handlers\base.py", line 220, in _get_response
    response = response.render()
               ^^^^^^^^^^^^^^^^^
  File "C:\Users\hp\AppData\Local\Programs\Python\Python312\Lib\site-packages\django\template\response.py", line 114, in render
    self.content = self.rendered_content
                   ^^^^^^^^^^^^^^^^^^^^^
  File "C:\Users\hp\AppData\Local\Programs\Python\Python312\Lib\site-packages\rest_framework\response.py", line 74, in rendered_content
    ret = renderer.render(self.data, accepted_media_type, context)
          ^^^^^^^^^^^^^^^^^^^^^^^^^^^^^^^^^^^^^^^^^^^^^^^^^^^^^^^^
  File "C:\Users\hp\AppData\Local\Programs\Python\Python312\Lib\site-packages\rest_framework\renderers.py", line 100, in render
    ret = json.dumps(
          ^^^^^^^^^^^
  File "C:\Users\hp\AppData\Local\Programs\Python\Python312\Lib\site-packages\rest_framework\utils\json.py", line 25, in dumps
    return json.dumps(*args, **kwargs)
           ^^^^^^^^^^^^^^^^^^^^^^^^^^^
  File "C:\Users\hp\AppData\Local\Programs\Python\Python312\Lib\json\__init__.py", line 238, in dumps
    **kw).encode(obj)
          ^^^^^^^^^^^
  File "C:\Users\hp\AppData\Local\Programs\Python\Python312\Lib\json\encoder.py", line 200, in encode
    chunks = self.iterencode(o, _one_shot=True)
             ^^^^^^^^^^^^^^^^^^^^^^^^^^^^^^^^^^
  File "C:\Users\hp\AppData\Local\Programs\Python\Python312\Lib\json\encoder.py", line 258, in iterencode
    return _iterencode(o, 0)
           ^^^^^^^^^^^^^^^^^
  File "C:\Users\hp\AppData\Local\Programs\Python\Python312\Lib\site-packages\rest_framework\utils\encoders.py", line 67, in default
    return super().default(obj)
           ^^^^^^^^^^^^^^^^^^^^
  File "C:\Users\hp\AppData\Local\Programs\Python\Python312\Lib\json\encoder.py", line 180, in default
    raise TypeError(f'Object of type {o.__class__.__name__} '
TypeError: Object of type User is not JSON serializable
2025-01-09 10:26:55,717 (INFO)- home.views- api-request-reached
2025-01-09 10:26:56,867 (INFO)- home.views- dhruvi
2025-01-09 10:26:56,926 (ERROR)- django.request- Internal Server Error: /api/login/
Traceback (most recent call last):
  File "C:\Users\hp\AppData\Local\Programs\Python\Python312\Lib\site-packages\django\core\handlers\exception.py", line 55, in inner
    response = get_response(request)
               ^^^^^^^^^^^^^^^^^^^^^
  File "C:\Users\hp\AppData\Local\Programs\Python\Python312\Lib\site-packages\django\core\handlers\base.py", line 220, in _get_response
    response = response.render()
               ^^^^^^^^^^^^^^^^^
  File "C:\Users\hp\AppData\Local\Programs\Python\Python312\Lib\site-packages\django\template\response.py", line 114, in render
    self.content = self.rendered_content
                   ^^^^^^^^^^^^^^^^^^^^^
  File "C:\Users\hp\AppData\Local\Programs\Python\Python312\Lib\site-packages\rest_framework\response.py", line 74, in rendered_content
    ret = renderer.render(self.data, accepted_media_type, context)
          ^^^^^^^^^^^^^^^^^^^^^^^^^^^^^^^^^^^^^^^^^^^^^^^^^^^^^^^^
  File "C:\Users\hp\AppData\Local\Programs\Python\Python312\Lib\site-packages\rest_framework\renderers.py", line 100, in render
    ret = json.dumps(
          ^^^^^^^^^^^
  File "C:\Users\hp\AppData\Local\Programs\Python\Python312\Lib\site-packages\rest_framework\utils\json.py", line 25, in dumps
    return json.dumps(*args, **kwargs)
           ^^^^^^^^^^^^^^^^^^^^^^^^^^^
  File "C:\Users\hp\AppData\Local\Programs\Python\Python312\Lib\json\__init__.py", line 238, in dumps
    **kw).encode(obj)
          ^^^^^^^^^^^
  File "C:\Users\hp\AppData\Local\Programs\Python\Python312\Lib\json\encoder.py", line 200, in encode
    chunks = self.iterencode(o, _one_shot=True)
             ^^^^^^^^^^^^^^^^^^^^^^^^^^^^^^^^^^
  File "C:\Users\hp\AppData\Local\Programs\Python\Python312\Lib\json\encoder.py", line 258, in iterencode
    return _iterencode(o, 0)
           ^^^^^^^^^^^^^^^^^
  File "C:\Users\hp\AppData\Local\Programs\Python\Python312\Lib\site-packages\rest_framework\utils\encoders.py", line 67, in default
    return super().default(obj)
           ^^^^^^^^^^^^^^^^^^^^
  File "C:\Users\hp\AppData\Local\Programs\Python\Python312\Lib\json\encoder.py", line 180, in default
    raise TypeError(f'Object of type {o.__class__.__name__} '
TypeError: Object of type User is not JSON serializable
2025-01-09 10:30:51,903 (INFO)- django.utils.autoreload- C:\Users\hp\OneDrive\Desktop\Examino\project\home\views.py changed, reloading.
2025-01-09 10:30:52,957 (INFO)- django.utils.autoreload- Watching for file changes with StatReloader
2025-01-09 10:31:17,003 (INFO)- django.utils.autoreload- C:\Users\hp\OneDrive\Desktop\Examino\project\home\views.py changed, reloading.
2025-01-09 10:31:17,981 (INFO)- django.utils.autoreload- Watching for file changes with StatReloader
2025-01-09 10:31:33,542 (ERROR)- django.request- Internal Server Error: /api/login/
Traceback (most recent call last):
  File "C:\Users\hp\AppData\Local\Programs\Python\Python312\Lib\site-packages\django\core\handlers\exception.py", line 55, in inner
    response = get_response(request)
               ^^^^^^^^^^^^^^^^^^^^^
  File "C:\Users\hp\AppData\Local\Programs\Python\Python312\Lib\site-packages\django\core\handlers\base.py", line 220, in _get_response
    response = response.render()
               ^^^^^^^^^^^^^^^^^
  File "C:\Users\hp\AppData\Local\Programs\Python\Python312\Lib\site-packages\django\template\response.py", line 114, in render
    self.content = self.rendered_content
                   ^^^^^^^^^^^^^^^^^^^^^
  File "C:\Users\hp\AppData\Local\Programs\Python\Python312\Lib\site-packages\rest_framework\response.py", line 74, in rendered_content
    ret = renderer.render(self.data, accepted_media_type, context)
          ^^^^^^^^^^^^^^^^^^^^^^^^^^^^^^^^^^^^^^^^^^^^^^^^^^^^^^^^
  File "C:\Users\hp\AppData\Local\Programs\Python\Python312\Lib\site-packages\rest_framework\renderers.py", line 100, in render
    ret = json.dumps(
          ^^^^^^^^^^^
  File "C:\Users\hp\AppData\Local\Programs\Python\Python312\Lib\site-packages\rest_framework\utils\json.py", line 25, in dumps
    return json.dumps(*args, **kwargs)
           ^^^^^^^^^^^^^^^^^^^^^^^^^^^
  File "C:\Users\hp\AppData\Local\Programs\Python\Python312\Lib\json\__init__.py", line 238, in dumps
    **kw).encode(obj)
          ^^^^^^^^^^^
  File "C:\Users\hp\AppData\Local\Programs\Python\Python312\Lib\json\encoder.py", line 200, in encode
    chunks = self.iterencode(o, _one_shot=True)
             ^^^^^^^^^^^^^^^^^^^^^^^^^^^^^^^^^^
  File "C:\Users\hp\AppData\Local\Programs\Python\Python312\Lib\json\encoder.py", line 258, in iterencode
    return _iterencode(o, 0)
           ^^^^^^^^^^^^^^^^^
  File "C:\Users\hp\AppData\Local\Programs\Python\Python312\Lib\site-packages\rest_framework\utils\encoders.py", line 67, in default
    return super().default(obj)
           ^^^^^^^^^^^^^^^^^^^^
  File "C:\Users\hp\AppData\Local\Programs\Python\Python312\Lib\json\encoder.py", line 180, in default
    raise TypeError(f'Object of type {o.__class__.__name__} '
TypeError: Object of type User is not JSON serializable
2025-01-09 11:54:32,072 (ERROR)- django.request- Internal Server Error: /api/login/
Traceback (most recent call last):
  File "C:\Users\hp\AppData\Local\Programs\Python\Python312\Lib\site-packages\django\core\handlers\exception.py", line 55, in inner
    response = get_response(request)
               ^^^^^^^^^^^^^^^^^^^^^
  File "C:\Users\hp\AppData\Local\Programs\Python\Python312\Lib\site-packages\django\core\handlers\base.py", line 220, in _get_response
    response = response.render()
               ^^^^^^^^^^^^^^^^^
  File "C:\Users\hp\AppData\Local\Programs\Python\Python312\Lib\site-packages\django\template\response.py", line 114, in render
    self.content = self.rendered_content
                   ^^^^^^^^^^^^^^^^^^^^^
  File "C:\Users\hp\AppData\Local\Programs\Python\Python312\Lib\site-packages\rest_framework\response.py", line 74, in rendered_content
    ret = renderer.render(self.data, accepted_media_type, context)
          ^^^^^^^^^^^^^^^^^^^^^^^^^^^^^^^^^^^^^^^^^^^^^^^^^^^^^^^^
  File "C:\Users\hp\AppData\Local\Programs\Python\Python312\Lib\site-packages\rest_framework\renderers.py", line 100, in render
    ret = json.dumps(
          ^^^^^^^^^^^
  File "C:\Users\hp\AppData\Local\Programs\Python\Python312\Lib\site-packages\rest_framework\utils\json.py", line 25, in dumps
    return json.dumps(*args, **kwargs)
           ^^^^^^^^^^^^^^^^^^^^^^^^^^^
  File "C:\Users\hp\AppData\Local\Programs\Python\Python312\Lib\json\__init__.py", line 238, in dumps
    **kw).encode(obj)
          ^^^^^^^^^^^
  File "C:\Users\hp\AppData\Local\Programs\Python\Python312\Lib\json\encoder.py", line 200, in encode
    chunks = self.iterencode(o, _one_shot=True)
             ^^^^^^^^^^^^^^^^^^^^^^^^^^^^^^^^^^
  File "C:\Users\hp\AppData\Local\Programs\Python\Python312\Lib\json\encoder.py", line 258, in iterencode
    return _iterencode(o, 0)
           ^^^^^^^^^^^^^^^^^
  File "C:\Users\hp\AppData\Local\Programs\Python\Python312\Lib\site-packages\rest_framework\utils\encoders.py", line 67, in default
    return super().default(obj)
           ^^^^^^^^^^^^^^^^^^^^
  File "C:\Users\hp\AppData\Local\Programs\Python\Python312\Lib\json\encoder.py", line 180, in default
    raise TypeError(f'Object of type {o.__class__.__name__} '
TypeError: Object of type User is not JSON serializable
2025-01-09 11:54:45,875 (ERROR)- django.request- Internal Server Error: /api/login/
Traceback (most recent call last):
  File "C:\Users\hp\AppData\Local\Programs\Python\Python312\Lib\site-packages\django\core\handlers\exception.py", line 55, in inner
    response = get_response(request)
               ^^^^^^^^^^^^^^^^^^^^^
  File "C:\Users\hp\AppData\Local\Programs\Python\Python312\Lib\site-packages\django\core\handlers\base.py", line 220, in _get_response
    response = response.render()
               ^^^^^^^^^^^^^^^^^
  File "C:\Users\hp\AppData\Local\Programs\Python\Python312\Lib\site-packages\django\template\response.py", line 114, in render
    self.content = self.rendered_content
                   ^^^^^^^^^^^^^^^^^^^^^
  File "C:\Users\hp\AppData\Local\Programs\Python\Python312\Lib\site-packages\rest_framework\response.py", line 74, in rendered_content
    ret = renderer.render(self.data, accepted_media_type, context)
          ^^^^^^^^^^^^^^^^^^^^^^^^^^^^^^^^^^^^^^^^^^^^^^^^^^^^^^^^
  File "C:\Users\hp\AppData\Local\Programs\Python\Python312\Lib\site-packages\rest_framework\renderers.py", line 100, in render
    ret = json.dumps(
          ^^^^^^^^^^^
  File "C:\Users\hp\AppData\Local\Programs\Python\Python312\Lib\site-packages\rest_framework\utils\json.py", line 25, in dumps
    return json.dumps(*args, **kwargs)
           ^^^^^^^^^^^^^^^^^^^^^^^^^^^
  File "C:\Users\hp\AppData\Local\Programs\Python\Python312\Lib\json\__init__.py", line 238, in dumps
    **kw).encode(obj)
          ^^^^^^^^^^^
  File "C:\Users\hp\AppData\Local\Programs\Python\Python312\Lib\json\encoder.py", line 200, in encode
    chunks = self.iterencode(o, _one_shot=True)
             ^^^^^^^^^^^^^^^^^^^^^^^^^^^^^^^^^^
  File "C:\Users\hp\AppData\Local\Programs\Python\Python312\Lib\json\encoder.py", line 258, in iterencode
    return _iterencode(o, 0)
           ^^^^^^^^^^^^^^^^^
  File "C:\Users\hp\AppData\Local\Programs\Python\Python312\Lib\site-packages\rest_framework\utils\encoders.py", line 67, in default
    return super().default(obj)
           ^^^^^^^^^^^^^^^^^^^^
  File "C:\Users\hp\AppData\Local\Programs\Python\Python312\Lib\json\encoder.py", line 180, in default
    raise TypeError(f'Object of type {o.__class__.__name__} '
TypeError: Object of type User is not JSON serializable
2025-01-09 12:00:31,469 (ERROR)- django.request- Internal Server Error: /api/login/
Traceback (most recent call last):
  File "C:\Users\hp\AppData\Local\Programs\Python\Python312\Lib\site-packages\django\core\handlers\exception.py", line 55, in inner
    response = get_response(request)
               ^^^^^^^^^^^^^^^^^^^^^
  File "C:\Users\hp\AppData\Local\Programs\Python\Python312\Lib\site-packages\django\core\handlers\base.py", line 220, in _get_response
    response = response.render()
               ^^^^^^^^^^^^^^^^^
  File "C:\Users\hp\AppData\Local\Programs\Python\Python312\Lib\site-packages\django\template\response.py", line 114, in render
    self.content = self.rendered_content
                   ^^^^^^^^^^^^^^^^^^^^^
  File "C:\Users\hp\AppData\Local\Programs\Python\Python312\Lib\site-packages\rest_framework\response.py", line 74, in rendered_content
    ret = renderer.render(self.data, accepted_media_type, context)
          ^^^^^^^^^^^^^^^^^^^^^^^^^^^^^^^^^^^^^^^^^^^^^^^^^^^^^^^^
  File "C:\Users\hp\AppData\Local\Programs\Python\Python312\Lib\site-packages\rest_framework\renderers.py", line 100, in render
    ret = json.dumps(
          ^^^^^^^^^^^
  File "C:\Users\hp\AppData\Local\Programs\Python\Python312\Lib\site-packages\rest_framework\utils\json.py", line 25, in dumps
    return json.dumps(*args, **kwargs)
           ^^^^^^^^^^^^^^^^^^^^^^^^^^^
  File "C:\Users\hp\AppData\Local\Programs\Python\Python312\Lib\json\__init__.py", line 238, in dumps
    **kw).encode(obj)
          ^^^^^^^^^^^
  File "C:\Users\hp\AppData\Local\Programs\Python\Python312\Lib\json\encoder.py", line 200, in encode
    chunks = self.iterencode(o, _one_shot=True)
             ^^^^^^^^^^^^^^^^^^^^^^^^^^^^^^^^^^
  File "C:\Users\hp\AppData\Local\Programs\Python\Python312\Lib\json\encoder.py", line 258, in iterencode
    return _iterencode(o, 0)
           ^^^^^^^^^^^^^^^^^
  File "C:\Users\hp\AppData\Local\Programs\Python\Python312\Lib\site-packages\rest_framework\utils\encoders.py", line 67, in default
    return super().default(obj)
           ^^^^^^^^^^^^^^^^^^^^
  File "C:\Users\hp\AppData\Local\Programs\Python\Python312\Lib\json\encoder.py", line 180, in default
    raise TypeError(f'Object of type {o.__class__.__name__} '
TypeError: Object of type User is not JSON serializable
2025-01-09 22:05:18,114 (INFO)- django.utils.autoreload- Watching for file changes with StatReloader
2025-01-09 22:05:39,525 (INFO)- django.utils.autoreload- C:\Users\hp\OneDrive\Desktop\Examino\project\api\urls.py changed, reloading.
2025-01-09 22:05:40,528 (INFO)- django.utils.autoreload- Watching for file changes with StatReloader
2025-01-09 22:06:56,906 (INFO)- django.utils.autoreload- C:\Users\hp\OneDrive\Desktop\Examino\project\home\views.py changed, reloading.
2025-01-09 22:06:57,976 (INFO)- django.utils.autoreload- Watching for file changes with StatReloader
2025-01-09 22:07:53,711 (INFO)- django.utils.autoreload- Watching for file changes with StatReloader
2025-01-09 22:08:25,468 (INFO)- django.utils.autoreload- C:\Users\hp\OneDrive\Desktop\Examino\project\home\urls.py changed, reloading.
2025-01-09 22:08:26,556 (INFO)- django.utils.autoreload- Watching for file changes with StatReloader
2025-01-09 22:08:37,673 (WARNING)- django.request- Not Found: /
2025-01-09 22:08:37,870 (WARNING)- django.request- Not Found: /favicon.ico
2025-01-09 22:08:43,998 (WARNING)- django.request- Method Not Allowed: /api/login/
2025-01-09 22:09:34,040 (ERROR)- django.request- Internal Server Error: /api/login/
Traceback (most recent call last):
  File "C:\Users\hp\AppData\Local\Programs\Python\Python312\Lib\site-packages\django\core\handlers\exception.py", line 55, in inner
    response = get_response(request)
               ^^^^^^^^^^^^^^^^^^^^^
  File "C:\Users\hp\AppData\Local\Programs\Python\Python312\Lib\site-packages\django\core\handlers\base.py", line 197, in _get_response
    response = wrapped_callback(request, *callback_args, **callback_kwargs)
               ^^^^^^^^^^^^^^^^^^^^^^^^^^^^^^^^^^^^^^^^^^^^^^^^^^^^^^^^^^^^
  File "C:\Users\hp\AppData\Local\Programs\Python\Python312\Lib\site-packages\django\views\decorators\csrf.py", line 65, in _view_wrapper
    return view_func(request, *args, **kwargs)
           ^^^^^^^^^^^^^^^^^^^^^^^^^^^^^^^^^^^
  File "C:\Users\hp\AppData\Local\Programs\Python\Python312\Lib\site-packages\django\views\generic\base.py", line 104, in view
    return self.dispatch(request, *args, **kwargs)
           ^^^^^^^^^^^^^^^^^^^^^^^^^^^^^^^^^^^^^^^
  File "C:\Users\hp\AppData\Local\Programs\Python\Python312\Lib\site-packages\rest_framework\views.py", line 511, in dispatch
    self.response = self.finalize_response(request, response, *args, **kwargs)
                    ^^^^^^^^^^^^^^^^^^^^^^^^^^^^^^^^^^^^^^^^^^^^^^^^^^^^^^^^^^
  File "C:\Users\hp\AppData\Local\Programs\Python\Python312\Lib\site-packages\rest_framework\views.py", line 423, in finalize_response
    assert isinstance(response, HttpResponseBase), (
           ^^^^^^^^^^^^^^^^^^^^^^^^^^^^^^^^^^^^^^
AssertionError: Expected a `Response`, `HttpResponse` or `StreamingHttpResponse` to be returned from the view, but received a `<class 'dict'>`
2025-01-09 22:11:49,808 (INFO)- django.utils.autoreload- C:\Users\hp\OneDrive\Desktop\Examino\project\home\views.py changed, reloading.
2025-01-09 22:11:50,837 (INFO)- django.utils.autoreload- Watching for file changes with StatReloader
2025-01-09 22:11:53,988 (WARNING)- django.request- Method Not Allowed: /api/login/
2025-01-09 22:12:43,450 (WARNING)- django.request- Method Not Allowed: /api/register/
2025-01-09 22:26:20,371 (WARNING)- django.request- Bad Request: /api/register/
2025-01-09 22:26:34,023 (WARNING)- django.request- Bad Request: /api/register/
2025-01-10 00:32:57,846 (INFO)- django.utils.autoreload- Watching for file changes with StatReloader
2025-01-10 01:12:36,489 (INFO)- django.utils.autoreload- Watching for file changes with StatReloader
2025-01-10 01:13:59,328 (INFO)- django.utils.autoreload- Watching for file changes with StatReloader
2025-01-10 01:14:08,064 (WARNING)- django.request- Not Found: /
2025-01-10 01:16:04,317 (WARNING)- django.request- Method Not Allowed: /api/login/
2025-01-10 01:31:59,016 (ERROR)- django.request- Internal Server Error: /api/admin-class/
Traceback (most recent call last):
  File "C:\Users\hp\AppData\Local\Programs\Python\Python312\Lib\site-packages\django\core\handlers\exception.py", line 55, in inner
    response = get_response(request)
               ^^^^^^^^^^^^^^^^^^^^^
  File "C:\Users\hp\AppData\Local\Programs\Python\Python312\Lib\site-packages\django\core\handlers\base.py", line 197, in _get_response
    response = wrapped_callback(request, *callback_args, **callback_kwargs)
               ^^^^^^^^^^^^^^^^^^^^^^^^^^^^^^^^^^^^^^^^^^^^^^^^^^^^^^^^^^^^
  File "C:\Users\hp\AppData\Local\Programs\Python\Python312\Lib\site-packages\django\views\decorators\csrf.py", line 65, in _view_wrapper
    return view_func(request, *args, **kwargs)
           ^^^^^^^^^^^^^^^^^^^^^^^^^^^^^^^^^^^
  File "C:\Users\hp\AppData\Local\Programs\Python\Python312\Lib\site-packages\django\views\generic\base.py", line 104, in view
    return self.dispatch(request, *args, **kwargs)
           ^^^^^^^^^^^^^^^^^^^^^^^^^^^^^^^^^^^^^^^
  File "C:\Users\hp\AppData\Local\Programs\Python\Python312\Lib\site-packages\rest_framework\views.py", line 511, in dispatch
    self.response = self.finalize_response(request, response, *args, **kwargs)
                    ^^^^^^^^^^^^^^^^^^^^^^^^^^^^^^^^^^^^^^^^^^^^^^^^^^^^^^^^^^
  File "C:\Users\hp\AppData\Local\Programs\Python\Python312\Lib\site-packages\rest_framework\views.py", line 423, in finalize_response
    assert isinstance(response, HttpResponseBase), (
           ^^^^^^^^^^^^^^^^^^^^^^^^^^^^^^^^^^^^^^
AssertionError: Expected a `Response`, `HttpResponse` or `StreamingHttpResponse` to be returned from the view, but received a `<class 'NoneType'>`
2025-01-10 01:32:02,639 (WARNING)- django.request- Bad Request: /api/admin-class/
2025-01-10 01:32:18,174 (WARNING)- django.request- Bad Request: /api/admin-class/
2025-01-10 09:56:00,455 (INFO)- django.utils.autoreload- Watching for file changes with StatReloader
